<?xml version='1.0'?>
<sdf version="1.7" >
    <model name='pendulm'>
        <pose>0.5 0.5 0 0 0 0</pose>
        <joint name="base2world" type="fixed">
            <pose>0 0 0 0 0 0</pose>
            <parent>world</parent>
            <child>base</child>
        </joint>
        <frame name="base_frame" attached_to="base">
            <pose>0 0 -0.2 0 0 0</pose>
          </frame>
        <link name="base">
            <pose>0 0 0.3 0 0 0</pose>
            <visual name="base_visual">
                <geometry>
                    <box>
                        <size>0.1 0.1 1</size>
                    </box>
                </geometry>
            </visual>
            <!-- <collision name="base_coll">
                <geometry>
                    <box>
                        <size>0.1 0.1 1</size>
                    </box>
                </geometry>
            </collision> -->
        </link>
        <link name="pendulum">
            <pose relative_to="joint">
                0.05 0 -0.25 0 0 0
            </pose>
            <visual name="pendulum_visual">
                <geometry>
                    <box>
                        <size>0.1 0.1 0.5</size>
                    </box>
                </geometry>
            </visual>
            <!-- <collision name="pendulum_coll">
                <geometry>
                    <box>
                        <size>0.1 0.1 0.5</size>
                    </box>
                </geometry>
            </collision> -->
        </link>
        <joint name="joint" type="revolute">
            <parent>base</parent>
            <child>pendulum</child>
            <pose relative_to="base_frame">
                0.05 0 0.70 1.57 0 0
            </pose>
            <axis>
                <xyz>1 0 0</xyz>
            </axis>
        </joint>
    </model>
</sdf>