<?xml version='1.0'?>
<sdf version='1.6'>
  <model name='t_model'>
    <plugin name='set_joint_velocity_plugin' filename='libjoint_controller_plugin.so'/>
    <link name='link_0'>
      <pose frame=''>0 0 0.02 0 0 0</pose>
      <visual name='visual'>
        <geometry>
          <box>
            <size>1 1 0.04</size>
          </box>
        </geometry>
        <material>
          <lighting>1</lighting>
          <script>
            <uri>file://media/materials/scripts/gazebo.material</uri>
            <name>Gazebo/Grey</name>
          </script>
          <emissive>0 0 0 1</emissive>
        </material>
      </visual>
      <!-- <inertial>
        <mass>100</mass>
        <inertia>
          <ixx>16.667</ixx>
          <ixy>0</ixy>
          <ixz>0</ixz>
          <iyy>16.667</iyy>
          <iyz>0</iyz>
          <izz>16.667</izz>
        </inertia>
        <pose frame=''>0 0 0 0 -0 0</pose>
      </inertial> -->
      <collision name="link_0_collision">
        <geometry>
          <box>
            <size>1 1 0.035</size>
          </box>
        </geometry>
      </collision>
    </link>
    <link name='link_1'>
      <pose >0 0 0.27 0 0 0</pose>
      <visual name='visual'>
        <geometry>
          <cylinder>
            <radius>0.05</radius>
            <length>0.5</length>
          </cylinder>
        </geometry>

      </visual>
      <collision name="link_1_collision">
        <geometry>
          <cylinder>
            <radius>0.05</radius>
            <length>0.5</length>
          </cylinder>
        </geometry>
      </collision>
    </link>
    <link name='link_2'>
      <inertial>
        <mass>0.00701193</mass>
        <inertia>
          <ixx>0.000238155</ixx>
          <ixy>0</ixy>
          <ixz>0</ixz>
          <iyy>0.000238155</iyy>
          <iyz>0</iyz>
          <izz>9.72896e-06</izz>
        </inertia>
        <pose frame=''>0 0 0 0 -0 0</pose>
      </inertial>
      <pose >0 0 0.575 1.58563 0 0</pose>
      <visual name='visual'>
        <pose >0 0 0 0 -0 0</pose>
        <geometry>
          <cylinder>
            <radius>0.05</radius>
            <length>0.6</length>
          </cylinder>
        </geometry>
        <material>
          <lighting>1</lighting>
          <script>
            <uri>file://media/materials/scripts/gazebo.material</uri>
            <name>Gazebo/Grey</name>
          </script>
          <emissive>0 0 0 1</emissive>
        </material>
      </visual>
    </link>
    <joint name='joint_0' type='fixed'>
      <parent>link_0</parent>
      <child>link_1</child>
    </joint>
    <joint name='joint_1' type='revolute'>
      <parent>link_1</parent>
      <child>link_2</child>
      <pose frame=''>0 0 0 0 -0 0</pose>
      <axis>
        <xyz>0 1 0</xyz>
        <limit>
          <lower>-1.79769e+308</lower>
          <upper>1.79769e+308</upper>
          <effort>-1</effort>
          <velocity>-1</velocity>
        </limit>
        <dynamics>
          <spring_reference>0</spring_reference>
          <spring_stiffness>0</spring_stiffness>
          <damping>0</damping>
        </dynamics>
      </axis>
      <physics>
        <ode>
          <limit>
            <cfm>0</cfm>
            <erp>0.2</erp>
          </limit>
          <suspension>
            <cfm>0</cfm>
            <erp>0.2</erp>
          </suspension>
        </ode>
      </physics>
    </joint>
  </model>
</sdf>